Workbook

Sheet README
A1: ISO 20022 Legacy-to-MX Migration Toolkit - Excel companion
A3: What this is: the analysis workbook for the Python toolkit that converts SWIFT MT103 payments into ISO 20022 pacs.008.001.08, validates them, and measures what the migration gains, loses or guesses.
A4: Data: 100 fully synthetic MT103 messages (Pakistan-centred corridors). 46 carry exactly one injected defect so detection can be measured. All names, accounts and BICs are invented.
A6: Sheets
A7: Summary - headline KPIs, status/category charts, scenario and address tables (all formulas).
A8: Results - one row per message (toolkit output). Findings - every rule hit. Lineage Data / Address Data - raw rows behind the pivots.
A9: Detection Eval - ground-truth check: was each injected defect caught by the rule that should catch it? Recall by defect type.
A10: Rule Catalog - all rules with severity and how often each fired. Mapping Matrix - MT103 field -> ISO 20022 element, with gain / guess / loss.
A11: Lineage - provenance of every ISO value (DIRECT, CODE, PARSED, INFERRED, FREETEXT). Business Case - 5-year NPV/IRR model with sensitivity.
A13: Colour code (financial-model convention): blue text = input you may change; black = formula; green = link to another sheet; yellow fill = scenario selector.
A14: To re-run the pipeline: python -m mt2iso generate && python -m mt2iso batch && python scripts/build_dashboard.py
A15: Important limits: the dataset is a stress test, not a sample of real traffic; the XSD is a subset authored from the published pacs.008.001.08 structure (validate against the official XSD before production);
... A17: Source for the deadline referenced in rule BR_ADDR_TWN_CTRY: Swift, 'Removal of unstructured address' (unstructured addresses NAK'd under CBPR+ from 14 November 2026).

Sheet Summary
A1: ISO 20022 Migration Toolkit - Results Dashboard
A2: Every figure below is a live formula over the Results / Findings / Lineage / Address sheets (output of the Python pipeline on the synthetic stress-test dataset).
A4: Headline KPIs
A5: Messages processed | B5: =COUNTA(Results!$A$2:$A$101) -> 100
A6: Converted & clean (no findings above INFO) | B6: =COUNTIF(Results!$G$2:$G$101,"PASS_CLEAN") -> 42
A7: Converted with warnings | B7: =COUNTIF(Results!$G$2:$G$101,"PASS_WITH_WARNINGS") -> 31
A8: Converted but failed validation (needs repair) | B8: =COUNTIF(Results!$G$2:$G$101,"FAILED_VALIDATION") -> 21
A9: Rejected at parse (no ISO message produced) | B9: =COUNTIF(Results!$G$2:$G$101,"REJECTED") -> 6
A10: Straight-through rate (clean + warnings) | B10: =(B6+B7)/B5 -> 0.73
A11: Repair rate (failed + rejected) | B11: =(B8+B9)/B5 -> 0.27
A12: Average quality score (0-100) | B12: =AVERAGE(Results!$H$2:$H$101) -> 81.74
A13: ISO leaf elements: deterministic (DIRECT+CODE) | B13: =(SUM(Results!$O$2:$O$101)+SUM(Results!$P$2:$P$101))/SUM(Results!$N$2:$N$101) -> 0.51954341
A14: ISO leaf elements: heuristic (PARSED) | B14: =SUM(Results!$Q$2:$Q$101)/SUM(Results!$N$2:$N$101) -> 0.20996195
A15: ISO leaf elements: inferred (not in MT103) | B15: =SUM(Results!$R$2:$R$101)/SUM(Results!$N$2:$N$101) -> 0.17883085
A16: ISO leaf elements: free text carried over | B16: =SUM(Results!$S$2:$S$101)/SUM(Results!$N$2:$N$101) -> 0.091663784
A17: Injected defects | B17: =COUNTIF(Results!$T$2:$T$101,"Yes") -> 46
A18: Injected defects detected by expected rule | B18: ='Detection Eval'!H19 -> 46
A19: Detection recall | B19: =IF(B17=0,0,B18/B17) -> 1
A20: False alarms: messages with NO injected defect but an ERROR | B20: =COUNTIFS(Results!$T$2:$T$101,"No",Results!$I$2:$I$101,">0") -> 0
A21: Parties with town+country in output (CBPR+ Nov-2026 ready) | B21: =SUM('Address Data'!$D$2:$D$189)/COUNTA('Address Data'!$A$2:$A$189) -> 0.97340426
A22: Parties with street/building structured | B22: =SUM('Address Data'!$E$2:$E$189)/COUNTA('Address Data'!$A$2:$A$189) -> 0.42553191
A24: Status distribution
A25: Status | B25: Messages | C25: Share
A26: PASS_CLEAN | B26: =COUNTIF(Results!$G$2:$G$101,A26) -> 42 | C26: =B26/$B$5 -> 0.42
A27: PASS_WITH_WARNINGS | B27: =COUNTIF(Results!$G$2:$G$101,A27) -> 31 | C27: =B27/$B$5 -> 0.31
A28: FAILED_VALIDATION | B28: =COUNTIF(Results!$G$2:$G$101,A28) -> 21 | C28: =B28/$B$5 -> 0.21
A29: REJECTED | B29: =COUNTIF(Results!$G$2:$G$101,A29) -> 6 | C29: =B29/$B$5 -> 0.06
A32: Findings by category
A33: Category | B33: Findings | C33: Share
A34: SYNTAX | B34: =COUNTIF(Findings!$C$2:$C$509,A34) -> 6 | C34: =B34/COUNTA(Findings!$A$2:$A$509) -> 0.011811024
A35: SCHEMA | B35: =COUNTIF(Findings!$C$2:$C$509,A35) -> 1 | C35: =B35/COUNTA(Findings!$A$2:$A$509) -> 0.0019685039
A36: BUSINESS | B36: =COUNTIF(Findings!$C$2:$C$509,A36) -> 110 | C36: =B36/COUNTA(Findings!$A$2:$A$509) -> 0.21653543
A37: ADDRESS | B37: =COUNTIF(Findings!$C$2:$C$509,A37) -> 5 | C37: =B37/COUNTA(Findings!$A$2:$A$509) -> 0.0098425197
A38: DATA_LOSS | B38: =COUNTIF(Findings!$C$2:$C$509,A38) -> 6 | C38: =B38/COUNTA(Findings!$A$2:$A$509) -> 0.011811024
A39: INFERENCE | B39: =COUNTIF(Findings!$C$2:$C$509,A39) -> 153 | C39: =B39/COUNTA(Findings!$A$2:$A$509) -> 0.3011811
A40: ENRICHMENT | B40: =COUNTIF(Findings!$C$2:$C$509,A40) -> 227 | C40: =B40/COUNTA(Findings!$A$2:$A$509) -> 0.44685039
A43: Outcome by business scenario
A44: Scenario | B44: Messages | C44: Clean | D44: Warnings | E44: Failed | F44: Rejected | G44: Repair rate | I44: Scenario key
A45: S1 | B45: =COUNTIF(Results!$B$2:$B$101,A45) -> 40 | C45: =COUNTIFS(Results!$B$2:$B$101,$A45,Results!$G$2:$G$101,"PASS_CLEAN") -> 18 | D45: =COUNTIFS(Results!$B$2:$B$101,$A45,Results!$G$2:$G$101,"PASS_WITH_WARNINGS") -> 11 | E45: =COUNTIFS(Results!$B$2:$B$101,$A45,Results!$G$2:$G$101,"FAILED_VALIDATION") -> 8 | F45: =COUNTIFS(Results!$B$2:$B$101,$A45,Results!$G$2:$G$101,"REJECTED") -> 3 | G45: =IF(B45=0,0,(E45+F45)/B45) -> 0.275 | I45: S1 Inbound worker remittance
A46: S2 | B46: =COUNTIF(Results!$B$2:$B$101,A46) -> 25 | C46: =COUNTIFS(Results!$B$2:$B$101,$A46,Results!$G$2:$G$101,"PASS_CLEAN") -> 9 | D46: =COUNTIFS(Results!$B$2:$B$101,$A46,Results!$G$2:$G$101,"PASS_WITH_WARNINGS") -> 9 | E46: =COUNTIFS(Results!$B$2:$B$101,$A46,Results!$G$2:$G$101,"FAILED_VALIDATION") -> 6 | F46: =COUNTIFS(Results!$B$2:$B$101,$A46,Results!$G$2:$G$101,"REJECTED") -> 1 | G46: =IF(B46=0,0,(E46+F46)/B46) -> 0.28 | I46: S2 Inbound trade
...

Sheet Business Case
A1: Business case - migrating a mid-size bank's cross-border flows to ISO 20022 data quality
A2: ALL inputs are ILLUSTRATIVE assumptions (blue). Replace them with the bank's own volumes, repair logs and screening statistics. They are not derived from the toolkit's synthetic data.
A3: Scenario selector (1 = Conservative, 2 = Base, 3 = Optimistic) >> | B3: 2
A4: Input | B4: Conservative | C4: Base | D4: Optimistic | E4: ACTIVE | F4: Unit / how to read
A5: Cross-border payments per year | B5: 400000 | C5: 600000 | D5: 800000 | E5: =CHOOSE($B$3,B5,C5,D5) -> 600000 | F5: messages
A6: Manual repair rate today | B6: 0.025 | C6: 0.04 | D6: 0.055 | E6: =CHOOSE($B$3,B6,C6,D6) -> 0.04 | F6: share of messages touched by an operator
A7: Relative cut in repairs after migration | B7: 0.15 | C7: 0.3 | D7: 0.45 | E7: =CHOOSE($B$3,B7,C7,D7) -> 0.3 | F7: structured data reduces free-text fixing
A8: Cost per manual repair | B8: 8 | C8: 12 | D8: 16 | E8: =CHOOSE($B$3,B8,C8,D8) -> 12 | F8: USD per repaired message (staff time)
A9: Sanctions-screening alert rate | B9: 0.02 | C9: 0.03 | D9: 0.04 | E9: =CHOOSE($B$3,B9,C9,D9) -> 0.03 | F9: share of messages generating an alert
A10: Relative cut in false-positive alerts | B10: 0.05 | C10: 0.12 | D10: 0.2 | E10: =CHOOSE($B$3,B10,C10,D10) -> 0.12 | F10: better name/address fields reduce fuzzy matches
A11: Cost per alert review | B11: 6 | C11: 10 | D11: 14 | E11: =CHOOSE($B$3,B11,C11,D11) -> 10 | F11: USD per alert (analyst time)
A12: One-off migration cost | B12: 900000 | C12: 650000 | D12: 500000 | E12: =CHOOSE($B$3,B12,C12,D12) -> 650000 | F12: USD: mapping, integration, testing, training (year 0)
A13: Annual run cost | B13: 150000 | C13: 110000 | D13: 80000 | E13: =CHOOSE($B$3,B13,C13,D13) -> 110000 | F13: USD per year: licences, support, monitoring
A14: Discount rate | B14: 0.12 | C14: 0.1 | D14: 0.08 | E14: =CHOOSE($B$3,B14,C14,D14) -> 0.1 | F14: cost of capital
A15: Volume growth | B15: 0.02 | C15: 0.05 | D15: 0.08 | E15: =CHOOSE($B$3,B15,C15,D15) -> 0.05 | F15: per year
A16: Payments with unstructured address today | B16: 0.4 | C16: 0.58 | D16: 0.6 | E16: =CHOOSE($B$3,B16,C16,D16) -> 0.58 | F16: share. Base echoes Swift's published network-wide July 2026 level (about 58-59%); a bank's own share will differ
... A18: Cost per NAK'd payment | B18: 20 | C18: 30 | D18: 45 | E18: =CHOOSE($B$3,B18,C18,D18) -> 30 | F18: USD: investigation, resubmission, customer compensation
A20: Five-year cash-flow model (USD)
A21: Year | B21: 0 | C21: 1 | D21: 2 | E21: 3 | F21: 4 | G21: 5
A22: Year index | B22: 0 | C22: 1 | D22: 2 | E22: 3 | F22: 4 | G22: 5
A23: Payments (messages) | C23: =$E$5*(1+$E$15)^(C$22-1) -> 600000 | D23: =$E$5*(1+$E$15)^(D$22-1) -> 630000 | E23: =$E$5*(1+$E$15)^(E$22-1) -> 661500 | F23: =$E$5*(1+$E$15)^(F$22-1) -> 694575 | G23: =$E$5*(1+$E$15)^(G$22-1) -> 729303.75
A24: Operational saving: fewer manual repairs | C24: =C23*$E$6*$E$7*$E$8 -> 86400 | D24: =D23*$E$6*$E$7*$E$8 -> 90720 | E24: =E23*$E$6*$E$7*$E$8 -> 95256 | F24: =F23*$E$6*$E$7*$E$8 -> 100018.8 | G24: =G23*$E$6*$E$7*$E$8 -> 105019.74
A25: Operational saving: fewer false-positive alerts | C25: =C23*$E$9*$E$10*$E$11 -> 21600 | D25: =D23*$E$9*$E$10*$E$11 -> 22680 | E25: =E23*$E$9*$E$10*$E$11 -> 23814 | F25: =F23*$E$9*$E$10*$E$11 -> 25004.7 | G25: =G23*$E$9*$E$10*$E$11 -> 26254.935
A26: Avoided cost: payments no longer NAK'd | C26: =C23*$E$16*$E$17*$E$18 -> 522000 | D26: =D23*$E$16*$E$17*$E$18 -> 548100 | E26: =E23*$E$16*$E$17*$E$18 -> 575505 | F26: =F23*$E$16*$E$17*$E$18 -> 604280.25 | G26: =G23*$E$16*$E$17*$E$18 -> 634494.26
A27: Total benefit | C27: =C24+C25+C26 -> 630000 | D27: =D24+D25+D26 -> 661500 | E27: =E24+E25+E26 -> 694575 | F27: =F24+F25+F26 -> 729303.75 | G27: =G24+G25+G26 -> 765768.94
A28: Run cost | C28: =-$E$13 -> -110000 | D28: =-$E$13 -> -110000 | E28: =-$E$13 -> -110000 | F28: =-$E$13 -> -110000 | G28: =-$E$13 -> -110000
A29: One-off migration cost | B29: =-$E$12 -> -650000 | C29: 0 | D29: 0 | E29: 0 | F29: 0 | G29: 0
A30: Net cash flow | B30: =B29 -> -650000 | C30: =C27+C28+C29 -> 520000 | D30: =D27+D28+D29 -> 551500 | E30: =E27+E28+E29 -> 584575 | F30: =F27+F28+F29 -> 619303.75 | G30: =G27+G28+G29 -> 655768.94
A31: Discount factor | B31: =1/(1+$E$14)^B22 -> 1 | C31: =1/(1+$E$14)^C22 -> 0.90909091 | D31: =1/(1+$E$14)^D22 -> 0.82644628 | E31: =1/(1+$E$14)^E22 -> 0.7513148 | F31: =1/(1+$E$14)^F22 -> 0.68301346 | G31: =1/(1+$E$14)^G22 -> 0.62092132
A32: Present value of net cash flow | B32: =B30*B31 -> -650000 | C32: =C30*C31 -> 472727.27 | D32: =D30*D31 -> 455785.12 | E32: =E30*E31 -> 439199.85 | F32: =F30*F31 -> 422992.79 | G32: =G30*G31 -> 407180.92
A33: Cumulative net cash flow (undiscounted) | B33: =B30 -> -650000 | C33: =B33+C30 -> -130000 | D33: =C33+D30 -> 421500 | E33: =D33+E30 -> 1006075 | F33: =E33+F30 -> 1625378.8 | G33: =F33+G30 -> 2281147.7
A34: Payback flag (1 = cumulative >= 0) | B34: 0 | C34: =IF(C33>=0,1,0) -> 0 | D34: =IF(D33>=0,1,0) -> 1 | E34: =IF(E33>=0,1,0) -> 1 | F34: =IF(F33>=0,1,0) -> 1 | G34: =IF(G33>=0,1,0) -> 1
A36: Key results
A37: Net present value, all benefits (USD) | B37: =SUM(B32:G32) -> 1547886
A38: Net present value, operational savings ONLY (USD) | B38: =-$E$12+SUMPRODUCT((C24:G24+C25:G25+C28:G28)*C31:G31) -> -618722.69
A39: IRR (all benefits) | B39: =IFERROR(IRR(B30:G30),"n/a") -> 0.80410275
A40: Payback year (cumulative cash turns positive) | B40: =IFERROR(MATCH(1,C34:G34,0),"beyond year 5") -> 2
A41: 5-year ROI ((benefits - costs) / costs) | B41: =(SUM(C27:G27)-($E$12+5*$E$13))/($E$12+5*$E$13) -> 1.9009564
A42: Share of 5-year benefits that is avoided NAK cost | B42: =SUM(C26:G26)/SUM(C27:G27) -> 0.82857143
A44: Reference only: repair rate in the toolkit's synthetic stress test (46% of messages carry an injected defect; NOT a prediction for real flows)
...

Sheet Results
A1: Msg ID | B1: Scenario | C1: Corridor | D1: Ccy | E1: Amount | F1: Injected defect | G1: Status | H1: Quality score | I1: Errors | J1: Warnings | K1: Inferences | L1: Data-loss flags | M1: Enrichments | N1: ISO leaf elements | O1: DIRECT | P1: CODE | Q1: PARSED | R1: INFERRED | S1: FREETEXT | T1: Injected?
A2: MSG001 | B2: S2 | C2: CN>PK | D2: JPY | E2: 259137.5 | F2: D10_JPY_DECIMALS | G2: FAILED_VALIDATION | H2: 60 | I2: 1 | J2: 1 | K2: 3 | L2: 0 | M2: 3 | N2: 32 | O2: 13 | P2: 3 | Q2: 7 | R2: 7 | S2: 2 | T2: =IF(F2="","No","Yes") -> Yes
A3: MSG002 | B3: S1 | C3: GB>PK | D3: GBP | E3: 319.92 | G3: PASS_CLEAN | H3: 96 | I3: 0 | J3: 0 | K3: 2 | L3: 0 | M3: 2 | N3: 28 | O3: 12 | P3: 1 | Q3: 6 | R3: 6 | S3: 3 | T3: =IF(F3="","No","Yes") -> No
A4: MSG003 | B4: S2 | C4: GB>PK | D4: USD | E4: 37086.39 | G4: PASS_CLEAN | H4: 96 | I4: 0 | J4: 0 | K4: 2 | L4: 0 | M4: 3 | N4: 31 | O4: 12 | P4: 3 | Q4: 9 | R4: 6 | S4: 1 | T4: =IF(F4="","No","Yes") -> No
A5: MSG004 | B5: S1 | C5: US>PK | D5: USD | E5: 3547.89 | G5: PASS_CLEAN | H5: 98 | I5: 0 | J5: 0 | K5: 1 | L5: 0 | M5: 2 | N5: 32 | O5: 16 | P5: 1 | Q5: 8 | R5: 5 | S5: 2 | T5: =IF(F5="","No","Yes") -> No
A6: MSG005 | B6: S2 | C6: AE>PK | D6: USD | E6: 208323.48 | G6: PASS_CLEAN | H6: 100 | I6: 0 | J6: 0 | K6: 0 | L6: 0 | M6: 3 | N6: 29 | O6: 14 | P6: 4 | Q6: 4 | R6: 4 | S6: 3 | T6: =IF(F6="","No","Yes") -> No
A7: MSG006 | B7: S2 | C7: CN>PK | D7: USD | E7: 128949.18 | F7: D03_BIC_FORMAT | G7: FAILED_VALIDATION | H7: 66 | I7: 1 | J7: 0 | K7: 2 | L7: 0 | M7: 2 | N7: 32 | O7: 14 | P7: 1 | Q7: 7 | R7: 6 | S7: 4 | T7: =IF(F7="","No","Yes") -> Yes
A8: MSG007 | B8: S2 | C8: DE>PK | D8: EUR | E8: 35564.72 | G8: PASS_WITH_WARNINGS | H8: 90 | I8: 0 | J8: 1 | K8: 3 | L8: 0 | M8: 3 | N8: 32 | O8: 12 | P8: 4 | Q8: 7 | R8: 7 | S8: 2 | T8: =IF(F8="","No","Yes") -> No
A9: MSG008 | B9: S3 | C9: PK>DE | D9: EUR | E9: 233841.58 | G9: PASS_WITH_WARNINGS | H9: 90 | I9: 0 | J9: 1 | K9: 3 | L9: 0 | M9: 3 | N9: 32 | O9: 13 | P9: 3 | Q9: 7 | R9: 7 | S9: 2 | T9: =IF(F9="","No","Yes") -> No
A10: MSG009 | B10: S3 | C10: PK>CN | D10: CNY | E10: 118676.32 | F10: D16_FX_NO_RATE | G10: PASS_WITH_WARNINGS | H10: 92 | I10: 0 | J10: 1 | K10: 1 | L10: 0 | M10: 3 | N10: 34 | O10: 15 | P10: 3 | Q10: 6 | R10: 5 | S10: 5 | T10: =IF(F10="","No","Yes") -> Yes
A11: MSG010 | B11: S1 | C11: US>PK | D11: USD | E11: 420.72 | F11: D06_ADDR_NO_COUNTRY | G11: FAILED_VALIDATION | H11: 68 | I11: 1 | J11: 0 | K11: 1 | L11: 0 | M11: 2 | N11: 29 | O11: 13 | P11: 2 | Q11: 6 | R11: 5 | S11: 3 | T11: =IF(F11="","No","Yes") -> Yes
A12: MSG011 | B12: S4 | C12: PK>GB | D12: GBP | E12: 23348.7 | G12: PASS_CLEAN | H12: 96 | I12: 0 | J12: 0 | K12: 2 | L12: 0 | M12: 3 | N12: 30 | O12: 12 | P12: 3 | Q12: 6 | R12: 6 | S12: 3 | T12: =IF(F12="","No","Yes") -> No
A13: MSG012 | B13: S1 | C13: GB>PK | D13: GBP | E13: 5935.77 | G13: PASS_CLEAN | H13: 98 | I13: 0 | J13: 0 | K13: 1 | L13: 0 | M13: 2 | N13: 31 | O13: 13 | P13: 2 | Q13: 10 | R13: 5 | S13: 1 | T13: =IF(F13="","No","Yes") -> No
A14: MSG013 | B14: S2 | C14: AE>PK | D14: USD | E14: 103213.65 | F14: D12_BAD_DATE | G14: REJECTED | H14: 0 | I14: 1 | J14: 0 | K14: 0 | L14: 0 | M14: 0 | N14: 0 | O14: 0 | P14: 0 | Q14: 0 | R14: 0 | S14: 0 | T14: =IF(F14="","No","Yes") -> Yes
A15: MSG014 | B15: S2 | C15: CN>PK | D15: USD | E15: 63092.47 | F15: D22_NON_IBAN_PK_ACCOUNT | G15: PASS_WITH_WARNINGS | H15: 90 | I15: 0 | J15: 1 | K15: 2 | L15: 0 | M15: 3 | N15: 29 | O15: 12 | P15: 3 | Q15: 4 | R15: 6 | S15: 4 | T15: =IF(F15="","No","Yes") -> Yes
A16: MSG015 | B16: S3 | C16: PK>AE | D16: USD | E16: 102388.73 | F16: D01_IBAN_CHECKSUM | G16: FAILED_VALIDATION | H16: 64 | I16: 1 | J16: 1 | K16: 1 | L16: 0 | M16: 2 | N16: 27 | O16: 15 | P16: 1 | Q16: 4 | R16: 5 | S16: 2 | T16: =IF(F16="","No","Yes") -> Yes
A17: MSG016 | B17: S1 | C17: US>PK | D17: USD | E17: 3072.61 | G17: PASS_CLEAN | H17: 96 | I17: 0 | J17: 0 | K17: 2 | L17: 0 | M17: 3 | N17: 34 | O17: 14 | P17: 2 | Q17: 8 | R17: 6 | S17: 4 | T17: =IF(F17="","No","Yes") -> No
A18: MSG017 | B18: S1 | C18: AE>PK | D18: USD | E18: 3811.57 | G18: PASS_CLEAN | H18: 100 | I18: 0 | J18: 0 | K18: 0 | L18: 0 | M18: 3 | N18: 27 | O18: 14 | P18: 2 | Q18: 4 | R18: 4 | S18: 3 | T18: =IF(F18="","No","Yes") -> No
A19: MSG018 | B19: S4 | C19: PK>US | D19: USD | E19: 38523.37 | G19: PASS_CLEAN | H19: 100 | I19: 0 | J19: 0 | K19: 0 | L19: 0 | M19: 3 | N19: 31 | O19: 14 | P19: 3 | Q19: 8 | R19: 4 | S19: 2 | T19: =IF(F19="","No","Yes") -> No
A20: MSG019 | B20: S4 | C20: US>PK | D20: USD | E20: 9227.23 | F20: D18_IBAN_COUNTRY_MISMATCH | G20: PASS_WITH_WARNINGS | H20: 92 | I20: 0 | J20: 1 | K20: 1 | L20: 0 | M20: 3 | N20: 33 | O20: 14 | P20: 4 | Q20: 10 | R20: 4 | S20: 1 | T20: =IF(F20="","No","Yes") -> Yes
A21: MSG020 | B21: S1 | C21: AE>PK | D21: AED | E21: 1284.09 | G21: PASS_CLEAN | H21: 96 | I21: 0 | J21: 0 | K21: 2 | L21: 0 | M21: 2 | N21: 29 | O21: 12 | P21: 2 | Q21: 7 | R21: 6 | S21: 2 | T21: =IF(F21="","No","Yes") -> No
A22: MSG021 | B22: S1 | C22: US>PK | D22: USD | E22: 4780.77 | F22: D15_CHARGE_RULE | G22: FAILED_VALIDATION | H22: 66 | I22: 1 | J22: 0 | K22: 2 | L22: 0 | M22: 2 | N22: 31 | O22: 14 | P22: 1 | Q22: 8 | R22: 6 | S22: 2 | T22: =IF(F22="","No","Yes") -> Yes
A23: MSG022 | B23: S1 | C23: SA>PK | D23: SAR | E23: 964.02 | G23: PASS_CLEAN | H23: 100 | I23: 0 | J23: 0 | K23: 0 | L23: 0 | M23: 2 | N23: 26 | O23: 14 | P23: 1 | Q23: 4 | R23: 4 | S23: 3 | T23: =IF(F23="","No","Yes") -> No
A24: MSG023 | B24: S1 | C24: GB>PK | D24: GBP | E24: 974.4 | F24: D08_NAME_AT_35 | G24: PASS_WITH_WARNINGS | H24: 90 | I24: 0 | J24: 1 | K24: 2 | L24: 1 | M24: 2 | N24: 31 | O24: 12 | P24: 1 | Q24: 7 | R24: 6 | S24: 5 | T24: =IF(F24="","No","Yes") -> Yes
A25: MSG024 | B25: S1 | C25: US>PK | D25: USD | E25: 5140.74 | F25: D09_REMIT_FULL | G25: PASS_WITH_WARNINGS | H25: 94 | I25: 0 | J25: 1 | K25: 0 | L25: 1 | M25: 2 | N25: 33 | O25: 14 | P25: 2 | Q25: 8 | R25: 4 | S25: 5 | T25: =IF(F25="","No","Yes") -> Yes
A26: MSG025 | B26: S1 | C26: GB>PK | D26: GBP | E26: 2597.56 | G26: PASS_CLEAN | H26: 96 | I26: 0 | J26: 0 | K26: 2 | L26: 0 | M26: 2 | N26: 32 | O26: 15 | P26: 2 | Q26: 7 | R26: 6 | S26: 2 | T26: =IF(F26="","No","Yes") -> No
A27: MSG026 | B27: S2 | C27: AE>PK | D27: USD | E27: 85800.41 | G27: PASS_CLEAN | H27: 96 | I27: 0 | J27: 0 | K27: 2 | L27: 0 | M27: 2 | N27: 30 | O27: 15 | P27: 1 | Q27: 5 | R27: 6 | S27: 3 | T27: =IF(F27="","No","Yes") -> No
A28: MSG027 | B28: S4 | C28: US>PK | D28: USD | E28: 10792.39 | F28: D06_ADDR_NO_COUNTRY | G28: FAILED_VALIDATION | H28: 66 | I28: 1 | J28: 0 | K28: 2 | L28: 0 | M28: 2 | N28: 31 | O28: 14 | P28: 4 | Q28: 4 | R28: 6 | S28: 3 | T28: =IF(F28="","No","Yes") -> Yes
A29: MSG028 | B29: S2 | C29: GB>PK | D29: USD | E29: 115283.39 | G29: PASS_WITH_WARNINGS | H29: 90 | I29: 0 | J29: 1 | K29: 3 | L29: 0 | M29: 3 | N29: 31 | O29: 11 | P29: 4 | Q29: 7 | R29: 7 | S29: 2 | T29: =IF(F29="","No","Yes") -> No
A30: MSG029 | B30: S1 | C30: AE>PK | D30: AED | E30: 5966.44 | F30: D22_NON_IBAN_PK_ACCOUNT | G30: PASS_WITH_WARNINGS | H30: 84 | I30: 0 | J30: 2 | K30: 3 | L30: 0 | M30: 3 | N30: 30 | O30: 12 | P30: 3 | Q30: 6 | R30: 7 | S30: 2 | T30: =IF(F30="","No","Yes") -> Yes
A31: MSG030 | B31: S2 | C31: US>PK | D31: USD | E31: 62635.52 | G31: PASS_CLEAN | H31: 96 | I31: 0 | J31: 0 | K31: 2 | L31: 0 | M31: 2 | N31: 31 | O31: 14 | P31: 1 | Q31: 8 | R31: 6 | S31: 2 | T31: =IF(F31="","No","Yes") -> No
A32: MSG031 | B32: S3 | C32: PK>DE | D32: EUR | E32: 161266.69 | G32: PASS_CLEAN | H32: 98 | I32: 0 | J32: 0 | K32: 1 | L32: 0 | M32: 3 | N32: 35 | O32: 13 | P32: 3 | Q32: 10 | R32: 5 | S32: 4 | T32: =IF(F32="","No","Yes") -> No
A33: MSG032 | B33: S2 | C33: AE>PK | D33: USD | E33: 184183.65 | G33: PASS_WITH_WARNINGS | H33: 92 | I33: 0 | J33: 1 | K33: 2 | L33: 0 | M33: 3 | N33: 30 | O33: 12 | P33: 4 | Q33: 5 | R33: 5 | S33: 4 | T33: =IF(F33="","No","Yes") -> No
A34: MSG033 | B34: S3 | C34: PK>AE | D34: XYZ | E34: 168073.96 | F34: D11_UNKNOWN_CCY | G34: FAILED_VALIDATION | H34: 68 | I34: 1 | J34: 0 | K34: 1 | L34: 0 | M34: 3 | N34: 31 | O34: 16 | P34: 5 | Q34: 4 | R34: 4 | S34: 2 | T34: =IF(F34="","No","Yes") -> Yes
A35: MSG034 | B35: S1 | C35: AE>PK | D35: AED | E35: 2575.42 | G35: PASS_CLEAN | H35: 96 | I35: 0 | J35: 0 | K35: 2 | L35: 0 | M35: 3 | N35: 29 | O35: 12 | P35: 3 | Q35: 5 | R35: 6 | S35: 3 | T35: =IF(F35="","No","Yes") -> No
A36: MSG035 | B36: S3 | C36: PK>AE | D36: USD | E36: 239987.15 | F36: D17_WEEKEND_DATE | G36: PASS_WITH_WARNINGS | H36: 90 | I36: 0 | J36: 1 | K36: 2 | L36: 0 | M36: 3 | N36: 34 | O36: 18 | P36: 3 | Q36: 2 | R36: 6 | S36: 5 | T36: =IF(F36="","No","Yes") -> Yes
A37: MSG036 | B37: S1 | C37: AE>PK | D37: AED | E37: 168.77 | F37: D03_BIC_FORMAT | G37: FAILED_VALIDATION | H37: 40 | I37: 2 | J37: 0 | K37: 0 | L37: 0 | M37: 2 | N37: 29 | O37: 15 | P37: 1 | Q37: 7 | R37: 4 | S37: 2 | T37: =IF(F37="","No","Yes") -> Yes
A38: MSG037 | B38: S3 | C38: PK>SG | D38: USD | E38: 182733.11 | G38: PASS_WITH_WARNINGS | H38: 90 | I38: 0 | J38: 1 | K38: 3 | L38: 0 | M38: 3 | N38: 33 | O38: 16 | P38: 3 | Q38: 5 | R38: 7 | S38: 2 | T38: =IF(F38="","No","Yes") -> No
A39: MSG038 | B39: S4 | C39: GB>PK | D39: GBP | E39: 18737.29 | G39: PASS_CLEAN | H39: 96 | I39: 0 | J39: 0 | K39: 2 | L39: 0 | M39: 3 | N39: 32 | O39: 16 | P39: 3 | Q39: 3 | R39: 6 | S39: 4 | T39: =IF(F39="","No","Yes") -> No
A40: MSG039 | B40: S2 | C40: AE>PK | D40: USD | E40: 195934.11 | F40: D08_NAME_AT_35 | G40: PASS_WITH_WARNINGS | H40: 92 | I40: 0 | J40: 1 | K40: 1 | L40: 1 | M40: 3 | N40: 34 | O40: 15 | P40: 4 | Q40: 6 | R40: 5 | S40: 4 | T40: =IF(F40="","No","Yes") -> Yes
...

Sheet Findings
A1: Msg ID | B1: Rule ID | C1: Category | D1: Severity | E1: Element / field | F1: Message
A2: MSG001 | B2: BR_AMT_DECIMALS | C2: BUSINESS | D2: ERROR | E2: /*/*/*[2]/*[2] | F2: JPY allows 0 decimals but amount is 259137.50
A3: MSG001 | B3: BR_E2E_NOTPROVIDED | C3: BUSINESS | D3: INFO | E3: CdtTrfTxInf/PmtId/EndToEndId | F3: No /ROC/ originator reference in :70:
A4: MSG001 | B4: INF_UETR_GENERATED | C4: INFERENCE | D4: WARNING | E4: CdtTrfTxInf/PmtId/UETR | F4: MT103 carries no UETR; a new one was minted, so the payment cannot be tracked end-to-end
A5: MSG001 | B5: INF_CHRG_AGENT_INFERRED | C5: INFERENCE | D5: INFO | E5: CdtTrfTxInf/ChrgsInf/Agt | F5: :71F: does not say which bank levied the charge; SHNGCNSHXXX was assumed
A6: MSG001 | B6: GAIN_STRUCT_ADDR | C6: ENRICHMENT | D6: INFO | E6: CdtTrfTxInf/Dbtr/PstlAdr | F6: Town and country extracted from free text into structured elements (CBPR+ hybrid-ready)
A7: MSG001 | B7: INF_CDTRAGT_INFERRED | C7: INFERENCE | D7: INFO | E7: CdtTrfTxInf/CdtrAgt | F7: No :57a: account-with institution; the receiving bank was assumed to be the creditor agent
A8: MSG001 | B8: GAIN_STRUCT_ADDR | C8: ENRICHMENT | D8: INFO | E8: CdtTrfTxInf/Cdtr/PstlAdr | F8: Town and country extracted from free text into structured elements (CBPR+ hybrid-ready)
A9: MSG001 | B9: GAIN_STRUCT_RMT | C9: ENRICHMENT | D9: INFO | E9: CdtTrfTxInf/RmtInf/Strd/RfrdDocInf | F9: Invoice number recovered from /INV/ code word into a structured, machine-readable element
A10: MSG002 | B10: BR_E2E_NOTPROVIDED | C10: BUSINESS | D10: INFO | E10: CdtTrfTxInf/PmtId/EndToEndId | F10: No /ROC/ originator reference in :70:
A11: MSG002 | B11: GAIN_STRUCT_ADDR | C11: ENRICHMENT | D11: INFO | E11: CdtTrfTxInf/Dbtr/PstlAdr | F11: Town and country extracted from free text into structured elements (CBPR+ hybrid-ready)
A12: MSG002 | B12: INF_DBTRAGT_INFERRED | C12: INFERENCE | D12: INFO | E12: CdtTrfTxInf/DbtrAgt | F12: No :52a: ordering institution; the sending bank was assumed to be the debtor agent
... A509: MSG100 | B509: GAIN_STRUCT_ADDR | C509: ENRICHMENT | D509: INFO | E509: CdtTrfTxInf/Cdtr/PstlAdr | F509: Town and country extracted from free text into structured elements (CBPR+ hybrid-ready)

Sheet Detection Eval
A1: Msg ID | B1: Injected defect | C1: Expected rule | D1: Detected (1/0) | F1: Defect type | G1: Injected | H1: Detected | I1: Recall
A2: MSG001 | B2: D10_JPY_DECIMALS | C2: BR_AMT_DECIMALS | D2: =IF(COUNTIFS(Findings!$A$2:$A$509,A2,Findings!$B$2:$B$509,C2)>0,1,0) -> 1 | F2: D01_IBAN_CHECKSUM | G2: =COUNTIF($B$2:$B$47,F2) -> 4 | H2: =SUMIF($B$2:$B$47,F2,$D$2:$D$47) -> 4 | I2: =IF(G2=0,0,H2/G2) -> 1
A3: MSG006 | B3: D03_BIC_FORMAT | C3: BR_BIC_CTRY | D3: =IF(COUNTIFS(Findings!$A$2:$A$509,A3,Findings!$B$2:$B$509,C3)>0,1,0) -> 1 | F3: D02_IBAN_LENGTH | G3: =COUNTIF($B$2:$B$47,F3) -> 2 | H3: =SUMIF($B$2:$B$47,F3,$D$2:$D$47) -> 2 | I3: =IF(G3=0,0,H3/G3) -> 1
A4: MSG009 | B4: D16_FX_NO_RATE | C4: BR_FX_RATE_MISSING | D4: =IF(COUNTIFS(Findings!$A$2:$A$509,A4,Findings!$B$2:$B$509,C4)>0,1,0) -> 1 | F4: D03_BIC_FORMAT | G4: =COUNTIF($B$2:$B$47,F4) -> 4 | H4: =SUMIF($B$2:$B$47,F4,$D$2:$D$47) -> 4 | I4: =IF(G4=0,0,H4/G4) -> 1
A5: MSG010 | B5: D06_ADDR_NO_COUNTRY | C5: BR_ADDR_TWN_CTRY | D5: =IF(COUNTIFS(Findings!$A$2:$A$509,A5,Findings!$B$2:$B$509,C5)>0,1,0) -> 1 | F5: D06_ADDR_NO_COUNTRY | G5: =COUNTIF($B$2:$B$47,F5) -> 5 | H5: =SUMIF($B$2:$B$47,F5,$D$2:$D$47) -> 5 | I5: =IF(G5=0,0,H5/G5) -> 1
A6: MSG013 | B6: D12_BAD_DATE | C6: SX_DATE_INVALID | D6: =IF(COUNTIFS(Findings!$A$2:$A$509,A6,Findings!$B$2:$B$509,C6)>0,1,0) -> 1 | F6: D07_ADDR_TOWN_ONLY | G6: =COUNTIF($B$2:$B$47,F6) -> 3 | H6: =SUMIF($B$2:$B$47,F6,$D$2:$D$47) -> 3 | I6: =IF(G6=0,0,H6/G6) -> 1
A7: MSG014 | B7: D22_NON_IBAN_PK_ACCOUNT | C7: BR_NON_IBAN_ACCT | D7: =IF(COUNTIFS(Findings!$A$2:$A$509,A7,Findings!$B$2:$B$509,C7)>0,1,0) -> 1 | F7: D08_NAME_AT_35 | G7: =COUNTIF($B$2:$B$47,F7) -> 3 | H7: =SUMIF($B$2:$B$47,F7,$D$2:$D$47) -> 3 | I7: =IF(G7=0,0,H7/G7) -> 1
A8: MSG015 | B8: D01_IBAN_CHECKSUM | C8: BR_IBAN_CHK | D8: =IF(COUNTIFS(Findings!$A$2:$A$509,A8,Findings!$B$2:$B$509,C8)>0,1,0) -> 1 | F8: D09_REMIT_FULL | G8: =COUNTIF($B$2:$B$47,F8) -> 3 | H8: =SUMIF($B$2:$B$47,F8,$D$2:$D$47) -> 3 | I8: =IF(G8=0,0,H8/G8) -> 1
A9: MSG019 | B9: D18_IBAN_COUNTRY_MISMATCH | C9: BR_IBAN_ADDR_MISMATCH | D9: =IF(COUNTIFS(Findings!$A$2:$A$509,A9,Findings!$B$2:$B$509,C9)>0,1,0) -> 1 | F9: D10_JPY_DECIMALS | G9: =COUNTIF($B$2:$B$47,F9) -> 2 | H9: =SUMIF($B$2:$B$47,F9,$D$2:$D$47) -> 2 | I9: =IF(G9=0,0,H9/G9) -> 1
A10: MSG021 | B10: D15_CHARGE_RULE | C10: BR_CHRG_RULE | D10: =IF(COUNTIFS(Findings!$A$2:$A$509,A10,Findings!$B$2:$B$509,C10)>0,1,0) -> 1 | F10: D11_UNKNOWN_CCY | G10: =COUNTIF($B$2:$B$47,F10) -> 2 | H10: =SUMIF($B$2:$B$47,F10,$D$2:$D$47) -> 2 | I10: =IF(G10=0,0,H10/G10) -> 1
A11: MSG023 | B11: D08_NAME_AT_35 | C11: DL_NAME_TRUNC_SUSPECT | D11: =IF(COUNTIFS(Findings!$A$2:$A$509,A11,Findings!$B$2:$B$509,C11)>0,1,0) -> 1 | F11: D12_BAD_DATE | G11: =COUNTIF($B$2:$B$47,F11) -> 2 | H11: =SUMIF($B$2:$B$47,F11,$D$2:$D$47) -> 2 | I11: =IF(G11=0,0,H11/G11) -> 1
A12: MSG024 | B12: D09_REMIT_FULL | C12: DL_RMT_TRUNC_SUSPECT | D12: =IF(COUNTIFS(Findings!$A$2:$A$509,A12,Findings!$B$2:$B$509,C12)>0,1,0) -> 1 | F12: D13_AMOUNT_NO_COMMA | G12: =COUNTIF($B$2:$B$47,F12) -> 2 | H12: =SUMIF($B$2:$B$47,F12,$D$2:$D$47) -> 2 | I12: =IF(G12=0,0,H12/G12) -> 1
A13: MSG027 | B13: D06_ADDR_NO_COUNTRY | C13: BR_ADDR_TWN_CTRY | D13: =IF(COUNTIFS(Findings!$A$2:$A$509,A13,Findings!$B$2:$B$509,C13)>0,1,0) -> 1 | F13: D15_CHARGE_RULE | G13: =COUNTIF($B$2:$B$47,F13) -> 2 | H13: =SUMIF($B$2:$B$47,F13,$D$2:$D$47) -> 2 | I13: =IF(G13=0,0,H13/G13) -> 1
... A18: MSG039 | B18: D08_NAME_AT_35 | C18: DL_NAME_TRUNC_SUSPECT | D18: =IF(COUNTIFS(Findings!$A$2:$A$509,A18,Findings!$B$2:$B$509,C18)>0,1,0) -> 1 | F18: D22_NON_IBAN_PK_ACCOUNT | G18: =COUNTIF($B$2:$B$47,F18) -> 4 | H18: =SUMIF($B$2:$B$47,F18,$D$2:$D$47) -> 4 | I18: =IF(G18=0,0,H18/G18) -> 1
A19: MSG040 | B19: D01_IBAN_CHECKSUM | C19: BR_IBAN_CHK | D19: =IF(COUNTIFS(Findings!$A$2:$A$509,A19,Findings!$B$2:$B$509,C19)>0,1,0) -> 1 | F19: TOTAL | G19: =SUM(G2:G18) -> 46 | H19: =SUM(H2:H18) -> 46 | I19: =IF(G19=0,0,H19/G19) -> 1
A20: MSG044 | B20: D17_WEEKEND_DATE | C20: BR_VALUE_DATE_WEEKEND | D20: =IF(COUNTIFS(Findings!$A$2:$A$509,A20,Findings!$B$2:$B$509,C20)>0,1,0) -> 1
A21: MSG045 | B21: D02_IBAN_LENGTH | C21: BR_IBAN_LEN | D21: =IF(COUNTIFS(Findings!$A$2:$A$509,A21,Findings!$B$2:$B$509,C21)>0,1,0) -> 1
A22: MSG049 | B22: D15_CHARGE_RULE | C22: BR_CHRG_RULE | D22: =IF(COUNTIFS(Findings!$A$2:$A$509,A22,Findings!$B$2:$B$509,C22)>0,1,0) -> 1
A23: MSG053 | B23: D01_IBAN_CHECKSUM | C23: BR_IBAN_CHK | D23: =IF(COUNTIFS(Findings!$A$2:$A$509,A23,Findings!$B$2:$B$509,C23)>0,1,0) -> 1
A24: MSG054 | B24: D19_MISSING_MANDATORY | C24: SX_MISSING_FIELD | D24: =IF(COUNTIFS(Findings!$A$2:$A$509,A24,Findings!$B$2:$B$509,C24)>0,1,0) -> 1
A25: MSG056 | B25: D11_UNKNOWN_CCY | C25: BR_CCY_UNKNOWN | D25: =IF(COUNTIFS(Findings!$A$2:$A$509,A25,Findings!$B$2:$B$509,C25)>0,1,0) -> 1
A26: MSG058 | B26: D13_AMOUNT_NO_COMMA | C26: SX_AMOUNT_FORMAT | D26: =IF(COUNTIFS(Findings!$A$2:$A$509,A26,Findings!$B$2:$B$509,C26)>0,1,0) -> 1
A27: MSG059 | B27: D22_NON_IBAN_PK_ACCOUNT | C27: BR_NON_IBAN_ACCT | D27: =IF(COUNTIFS(Findings!$A$2:$A$509,A27,Findings!$B$2:$B$509,C27)>0,1,0) -> 1
A28: MSG060 | B28: D09_REMIT_FULL | C28: DL_RMT_TRUNC_SUSPECT | D28: =IF(COUNTIFS(Findings!$A$2:$A$509,A28,Findings!$B$2:$B$509,C28)>0,1,0) -> 1
A29: MSG061 | B29: D16_FX_NO_RATE | C29: BR_FX_RATE_MISSING | D29: =IF(COUNTIFS(Findings!$A$2:$A$509,A29,Findings!$B$2:$B$509,C29)>0,1,0) -> 1
A30: MSG063 | B30: D13_AMOUNT_NO_COMMA | C30: SX_AMOUNT_FORMAT | D30: =IF(COUNTIFS(Findings!$A$2:$A$509,A30,Findings!$B$2:$B$509,C30)>0,1,0) -> 1
A31: MSG066 | B31: D22_NON_IBAN_PK_ACCOUNT | C31: BR_NON_IBAN_ACCT | D31: =IF(COUNTIFS(Findings!$A$2:$A$509,A31,Findings!$B$2:$B$509,C31)>0,1,0) -> 1
... A47: MSG099 | B47: D07_ADDR_TOWN_ONLY | C47: INF_CTRY_FROM_TOWN | D47: =IF(COUNTIFS(Findings!$A$2:$A$509,A47,Findings!$B$2:$B$509,C47)>0,1,0) -> 1

Sheet Rule Catalog
A1: Rule ID | B1: Category | C1: Severity | D1: What it checks | E1: Times fired (this run)
A2: SX_MISSING_FIELD | B2: SYNTAX | C2: ERROR | D2: Mandatory MT103 field missing - message cannot be translated | E2: =COUNTIF(Findings!$B$2:$B$509,A2) -> 2
A3: SX_DATE_INVALID | B3: SYNTAX | C3: ERROR | D3: Value date in :32A: is not a real calendar date | E3: =COUNTIF(Findings!$B$2:$B$509,A3) -> 2
A4: SX_AMOUNT_FORMAT | B4: SYNTAX | C4: ERROR | D4: Amount not in SWIFT format (digits with a decimal comma) | E4: =COUNTIF(Findings!$B$2:$B$509,A4) -> 2
A5: SX_FIELD_FORMAT | B5: SYNTAX | C5: ERROR | D5: Field does not match its FIN format definition | E5: =COUNTIF(Findings!$B$2:$B$509,A5) -> 0
A6: SX_CODE_INVALID | B6: SYNTAX | C6: ERROR | D6: Code word not in the allowed list for the field | E6: =COUNTIF(Findings!$B$2:$B$509,A6) -> 0
A7: SX_LINE_LENGTH | B7: SYNTAX | C7: ERROR | D7: Free-text line exceeds the 35-character FIN limit | E7: =COUNTIF(Findings!$B$2:$B$509,A7) -> 0
A8: SX_FIELD_LINES | B8: SYNTAX | C8: ERROR | D8: Too many lines for the field | E8: =COUNTIF(Findings!$B$2:$B$509,A8) -> 0
A9: XSD_001 | B9: SCHEMA | C9: ERROR | D9: Output violates the pacs.008 XSD (structure, order, type facet) | E9: =COUNTIF(Findings!$B$2:$B$509,A9) -> 1
A10: BR_BIC_FMT | B10: BUSINESS | C10: ERROR | D10: BIC does not match the 8/11-character BIC pattern | E10: =COUNTIF(Findings!$B$2:$B$509,A10) -> 1
A11: BR_BIC_CTRY | B11: BUSINESS | C11: ERROR | D11: BIC characters 5-6 are not a valid ISO 3166 country | E11: =COUNTIF(Findings!$B$2:$B$509,A11) -> 3
A12: BR_IBAN_CHK | B12: BUSINESS | C12: ERROR | D12: IBAN fails the ISO 13616 mod-97 check | E12: =COUNTIF(Findings!$B$2:$B$509,A12) -> 6
A13: BR_IBAN_LEN | B13: BUSINESS | C13: ERROR | D13: IBAN length differs from the registry length for its country | E13: =COUNTIF(Findings!$B$2:$B$509,A13) -> 2
... A37: GAIN_STRUCT_RMT | B37: ENRICHMENT | C37: INFO | D37: Code-word remittance data turned into structured Strd elements | E37: =COUNTIF(Findings!$B$2:$B$509,A37) -> 47

Sheet Mapping Matrix
A1: MT103 field | B1: Meaning | C1: ISO 20022 target (pacs.008.001.08) | D1: Method | E1: MT constraint | F1: ISO 20022 capability | G1: Effect | H1: Notes
A2: :20: | B2: Sender's reference | C2: GrpHdr/MsgId; PmtId/InstrId; PmtId/TxId | D2: DIRECT | E2: 16 chars | F2: 35 chars per ID | G2: NEUTRAL | H2: Same value reused for three IDs
A3: :23B: | B3: Bank operation code | C3: PmtTpInf/SvcLvl/Prtry (SPRI, SSTD, SPAY) | D3: CODE | E3: 5 codes | F3: Service level / category purpose | G3: NEUTRAL | H3: CRED is the default and produces no element. Mapping decision of this toolkit; CBPR+ guidelines may differ
A4: :32A: | B4: Value date, currency, amount | C4: IntrBkSttlmDt; IntrBkSttlmAmt (+Ccy) | D4: DIRECT | E4: Decimal comma; YYMMDD | F4: xs:date, decimal point, 18 digits | G4: NEUTRAL | H4: Format conversion only; decimals checked per ISO 4217
A5: :33B: | B5: Instructed amount | C5: InstdAmt (+Ccy) | D5: DIRECT | E5: Optional | F5: Native element | G5: NEUTRAL
A6: :36: | B6: Exchange rate | C6: XchgRate | D6: DIRECT | E6: Decimal comma | F6: Decimal point, up to 10 decimals | G6: NEUTRAL | H6: Rule: 33B currency <> 32A currency should come with a rate
A7: :50A: | B7: Ordering customer (BIC) | C7: Dbtr/Id/OrgId/AnyBIC | D7: DIRECT | E7: BIC only, no name | F7: Name + address + IDs | G7: LOSS | H7: No name available, flagged by BR_NAME_REQ
A8: :50K: | B8: Ordering customer (free text) | C8: Dbtr/Nm; Dbtr/PstlAdr/* | D8: PARSED | E8: 4x35 chars, name+address mixed | F8: Nm 140; structured address; 16+ elements | G8: GUESS | H8: Address structured by heuristics; leftovers go to AdrLine (hybrid)
A9: :50F: | B9: Ordering customer (structured) | C9: Dbtr/Nm; Dbtr/PstlAdr/TwnNm,Ctry,AdrLine | D9: DIRECT | E9: Numbered lines 1/-8/ | F9: Native structure | G9: GAIN | H9: Lines 4/-8/ not carried -> DL_UNMAPPED_50F_LINES
A10: :50a: account | B10: Ordering account | C10: DbtrAcct/Id/IBAN or Othr/Id | D10: DIRECT | E10: Account in first line | F10: IBAN vs other account typed | G10: GAIN | H10: IBAN checksum and length validated
A11: :52A/D: | B11: Ordering institution | C11: DbtrAgt/FinInstnId/BICFI or Nm+PstlAdr | D11: DIRECT | E11: Optional | F11: Mandatory in pacs.008 | G11: GUESS | H11: If absent the sending bank BIC is assumed (INF_DBTRAGT_INFERRED)
A12: :53A: | B12: Sender's correspondent | C12: SttlmInf/InstgRmbrsmntAgt; SttlmMtd=INGA | D12: DIRECT | E12: Optional | F12: Settlement instruction block | G12: NEUTRAL | H12: Settlement-method choice is simplified
A13: :54A: | B13: Receiver's correspondent | C13: SttlmInf/InstdRmbrsmntAgt | D13: DIRECT | E13: Optional | F13: Settlement instruction block | G13: NEUTRAL
A14: :56A/D: | B14: Intermediary institution | C14: IntrmyAgt1 | D14: DIRECT | E14: Optional | F14: Up to 3 intermediaries | G14: NEUTRAL
A15: :57A/D: | B15: Account with institution | C15: CdtrAgt/FinInstnId | D15: DIRECT | E15: Optional | F15: Mandatory in pacs.008 | G15: GUESS | H15: If absent the receiving bank BIC is assumed (INF_CDTRAGT_INFERRED)
A16: :59: | B16: Beneficiary (free text) | C16: Cdtr/Nm; Cdtr/PstlAdr/*; CdtrAcct | D16: PARSED | E16: 4x35 chars; name+address mixed | F16: Structured address | G16: GUESS | H16: Same heuristics as 50K
A17: :59F: | B17: Beneficiary (structured) | C17: Cdtr/Nm; Cdtr/PstlAdr/* | D17: DIRECT | E17: Numbered lines | F17: Native structure | G17: GAIN
A18: :70: | B18: Remittance information | C18: RmtInf/Ustrd; RmtInf/Strd/RfrdDocInf; CdtrRefInf | D18: CODE / FREETEXT | E18: 4x35 = 140 chars | F18: Ustrd 140 + structured blocks | G18: GAIN | H18: /INV/ -> CINV document number; /RFB/ -> creditor reference; /ROC/ -> EndToEndId
A19: :70: /ROC/ | B19: Ordering customer's reference | C19: PmtId/EndToEndId | D19: CODE | E19: Buried in free text | F19: Dedicated element | G19: GAIN | H19: Absent -> NOTPROVIDED (DL / BR_E2E_NOTPROVIDED)
A20: :71A: | B20: Details of charges | C20: ChrgBr (OUR=DEBT, BEN=CRED, SHA=SHAR) | D20: CODE | E20: 3 codes | F20: 4 codes (adds SLEV) | G20: NEUTRAL | H20: Charge-combination rules checked at MT level
A21: :71F:/:71G: | B21: Sender's / receiver's charges | C21: ChrgsInf/Amt + Agt | D21: DIRECT / INFERRED | E21: No bank named | F21: Agent mandatory | G21: GUESS | H21: Charging agent assumed (INF_CHRG_AGENT_INFERRED)
A22: :72: | B22: Sender to receiver info | C22: InstrForNxtAgt/InstrInf | D22: FREETEXT | E22: 6x35 with code words | F22: Coded instruction options | G22: NEUTRAL | H22: Stays unstructured here
A23: :77B: | B23: Regulatory reporting | C23: RgltryRptg/Dtls/Inf | D23: FREETEXT | E23: 3x35 | F23: Structured regulatory details | G23: NEUTRAL | H23: Could be structured further (authority, country, code)
A24: {3:{121:}} | B24: UETR (gpi tracker) | C24: PmtId/UETR | D24: DIRECT / INFERRED | E24: Optional | F24: UUIDv4 | G24: GUESS | H24: If absent a UETR is minted (INF_UETR_GENERATED)
A25: {1:}/{2:} | B25: Sender / receiver LT | C25: InstgAgt, InstdAgt BICFI | D25: DIRECT | E25: LT address | F25: Agent elements | G25: NEUTRAL | H25: BIC8 + branch extracted from the 12-char LT address

Sheet Lineage
A1: Where did each ISO 20022 value come from?
A2: Counts of populated leaf elements across all converted messages (live COUNTIFS over 'Lineage Data').
A4: Element group | B4: DIRECT | C4: CODE | D4: PARSED | E4: INFERRED | F4: FREETEXT | G4: Total | H4: Deterministic % | I4: Guessed % (PARSED+INFERRED)
A5: Cdtr | B5: =COUNTIFS('Lineage Data'!$C$2:$C$2892,$A5,'Lineage Data'!$E$2:$E$2892,B$4) -> 104 | C5: =COUNTIFS('Lineage Data'!$C$2:$C$2892,$A5,'Lineage Data'!$E$2:$E$2892,C$4) -> 0 | D5: =COUNTIFS('Lineage Data'!$C$2:$C$2892,$A5,'Lineage Data'!$E$2:$E$2892,D$4) -> 289 | E5: =COUNTIFS('Lineage Data'!$C$2:$C$2892,$A5,'Lineage Data'!$E$2:$E$2892,E$4) -> 1 | F5: =COUNTIFS('Lineage Data'!$C$2:$C$2892,$A5,'Lineage Data'!$E$2:$E$2892,F$4) -> 61 | G5: =SUM(B5:F5) -> 455 | H5: =IF(G5=0,0,(B5+C5)/G5) -> 0.22857143 | I5: =IF(G5=0,0,(D5+E5)/G5) -> 0.63736264
A6: CdtrAcct | B6: =COUNTIFS('Lineage Data'!$C$2:$C$2892,$A6,'Lineage Data'!$E$2:$E$2892,B$4) -> 94 | C6: =COUNTIFS('Lineage Data'!$C$2:$C$2892,$A6,'Lineage Data'!$E$2:$E$2892,C$4) -> 0 | D6: =COUNTIFS('Lineage Data'!$C$2:$C$2892,$A6,'Lineage Data'!$E$2:$E$2892,D$4) -> 0 | E6: =COUNTIFS('Lineage Data'!$C$2:$C$2892,$A6,'Lineage Data'!$E$2:$E$2892,E$4) -> 0 | F6: =COUNTIFS('Lineage Data'!$C$2:$C$2892,$A6,'Lineage Data'!$E$2:$E$2892,F$4) -> 0 | G6: =SUM(B6:F6) -> 94 | H6: =IF(G6=0,0,(B6+C6)/G6) -> 1 | I6: =IF(G6=0,0,(D6+E6)/G6) -> 0
A7: CdtrAgt | B7: =COUNTIFS('Lineage Data'!$C$2:$C$2892,$A7,'Lineage Data'!$E$2:$E$2892,B$4) -> 31 | C7: =COUNTIFS('Lineage Data'!$C$2:$C$2892,$A7,'Lineage Data'!$E$2:$E$2892,C$4) -> 0 | D7: =COUNTIFS('Lineage Data'!$C$2:$C$2892,$A7,'Lineage Data'!$E$2:$E$2892,D$4) -> 0 | E7: =COUNTIFS('Lineage Data'!$C$2:$C$2892,$A7,'Lineage Data'!$E$2:$E$2892,E$4) -> 63 | F7: =COUNTIFS('Lineage Data'!$C$2:$C$2892,$A7,'Lineage Data'!$E$2:$E$2892,F$4) -> 0 | G7: =SUM(B7:F7) -> 94 | H7: =IF(G7=0,0,(B7+C7)/G7) -> 0.32978723 | I7: =IF(G7=0,0,(D7+E7)/G7) -> 0.67021277
A8: ChrgBr | B8: =COUNTIFS('Lineage Data'!$C$2:$C$2892,$A8,'Lineage Data'!$E$2:$E$2892,B$4) -> 0 | C8: =COUNTIFS('Lineage Data'!$C$2:$C$2892,$A8,'Lineage Data'!$E$2:$E$2892,C$4) -> 94 | D8: =COUNTIFS('Lineage Data'!$C$2:$C$2892,$A8,'Lineage Data'!$E$2:$E$2892,D$4) -> 0 | E8: =COUNTIFS('Lineage Data'!$C$2:$C$2892,$A8,'Lineage Data'!$E$2:$E$2892,E$4) -> 0 | F8: =COUNTIFS('Lineage Data'!$C$2:$C$2892,$A8,'Lineage Data'!$E$2:$E$2892,F$4) -> 0 | G8: =SUM(B8:F8) -> 94 | H8: =IF(G8=0,0,(B8+C8)/G8) -> 1 | I8: =IF(G8=0,0,(D8+E8)/G8) -> 0
A9: ChrgsInf | B9: =COUNTIFS('Lineage Data'!$C$2:$C$2892,$A9,'Lineage Data'!$E$2:$E$2892,B$4) -> 23 | C9: =COUNTIFS('Lineage Data'!$C$2:$C$2892,$A9,'Lineage Data'!$E$2:$E$2892,C$4) -> 0 | D9: =COUNTIFS('Lineage Data'!$C$2:$C$2892,$A9,'Lineage Data'!$E$2:$E$2892,D$4) -> 0 | E9: =COUNTIFS('Lineage Data'!$C$2:$C$2892,$A9,'Lineage Data'!$E$2:$E$2892,E$4) -> 23 | F9: =COUNTIFS('Lineage Data'!$C$2:$C$2892,$A9,'Lineage Data'!$E$2:$E$2892,F$4) -> 0 | G9: =SUM(B9:F9) -> 46 | H9: =IF(G9=0,0,(B9+C9)/G9) -> 0.5 | I9: =IF(G9=0,0,(D9+E9)/G9) -> 0.5
A10: Dbtr | B10: =COUNTIFS('Lineage Data'!$C$2:$C$2892,$A10,'Lineage Data'!$E$2:$E$2892,B$4) -> 108 | C10: =COUNTIFS('Lineage Data'!$C$2:$C$2892,$A10,'Lineage Data'!$E$2:$E$2892,C$4) -> 0 | D10: =COUNTIFS('Lineage Data'!$C$2:$C$2892,$A10,'Lineage Data'!$E$2:$E$2892,D$4) -> 318 | E10: =COUNTIFS('Lineage Data'!$C$2:$C$2892,$A10,'Lineage Data'!$E$2:$E$2892,E$4) -> 2 | F10: =COUNTIFS('Lineage Data'!$C$2:$C$2892,$A10,'Lineage Data'!$E$2:$E$2892,F$4) -> 52 | G10: =SUM(B10:F10) -> 480 | H10: =IF(G10=0,0,(B10+C10)/G10) -> 0.225 | I10: =IF(G10=0,0,(D10+E10)/G10) -> 0.66666667
A11: DbtrAcct | B11: =COUNTIFS('Lineage Data'!$C$2:$C$2892,$A11,'Lineage Data'!$E$2:$E$2892,B$4) -> 94 | C11: =COUNTIFS('Lineage Data'!$C$2:$C$2892,$A11,'Lineage Data'!$E$2:$E$2892,C$4) -> 0 | D11: =COUNTIFS('Lineage Data'!$C$2:$C$2892,$A11,'Lineage Data'!$E$2:$E$2892,D$4) -> 0 | E11: =COUNTIFS('Lineage Data'!$C$2:$C$2892,$A11,'Lineage Data'!$E$2:$E$2892,E$4) -> 0 | F11: =COUNTIFS('Lineage Data'!$C$2:$C$2892,$A11,'Lineage Data'!$E$2:$E$2892,F$4) -> 0 | G11: =SUM(B11:F11) -> 94 | H11: =IF(G11=0,0,(B11+C11)/G11) -> 1 | I11: =IF(G11=0,0,(D11+E11)/G11) -> 0
A12: DbtrAgt | B12: =COUNTIFS('Lineage Data'!$C$2:$C$2892,$A12,'Lineage Data'!$E$2:$E$2892,B$4) -> 53 | C12: =COUNTIFS('Lineage Data'!$C$2:$C$2892,$A12,'Lineage Data'!$E$2:$E$2892,C$4) -> 0 | D12: =COUNTIFS('Lineage Data'!$C$2:$C$2892,$A12,'Lineage Data'!$E$2:$E$2892,D$4) -> 0 | E12: =COUNTIFS('Lineage Data'!$C$2:$C$2892,$A12,'Lineage Data'!$E$2:$E$2892,E$4) -> 41 | F12: =COUNTIFS('Lineage Data'!$C$2:$C$2892,$A12,'Lineage Data'!$E$2:$E$2892,F$4) -> 0 | G12: =SUM(B12:F12) -> 94 | H12: =IF(G12=0,0,(B12+C12)/G12) -> 0.56382979 | I12: =IF(G12=0,0,(D12+E12)/G12) -> 0.43617021
A13: GrpHdr | B13: =COUNTIFS('Lineage Data'!$C$2:$C$2892,$A13,'Lineage Data'!$E$2:$E$2892,B$4) -> 101 | C13: =COUNTIFS('Lineage Data'!$C$2:$C$2892,$A13,'Lineage Data'!$E$2:$E$2892,C$4) -> 0 | D13: =COUNTIFS('Lineage Data'!$C$2:$C$2892,$A13,'Lineage Data'!$E$2:$E$2892,D$4) -> 0 | E13: =COUNTIFS('Lineage Data'!$C$2:$C$2892,$A13,'Lineage Data'!$E$2:$E$2892,E$4) -> 282 | F13: =COUNTIFS('Lineage Data'!$C$2:$C$2892,$A13,'Lineage Data'!$E$2:$E$2892,F$4) -> 0 | G13: =SUM(B13:F13) -> 383 | H13: =IF(G13=0,0,(B13+C13)/G13) -> 0.26370757 | I13: =IF(G13=0,0,(D13+E13)/G13) -> 0.73629243
A14: InstdAgt | B14: =COUNTIFS('Lineage Data'!$C$2:$C$2892,$A14,'Lineage Data'!$E$2:$E$2892,B$4) -> 94 | C14: =COUNTIFS('Lineage Data'!$C$2:$C$2892,$A14,'Lineage Data'!$E$2:$E$2892,C$4) -> 0 | D14: =COUNTIFS('Lineage Data'!$C$2:$C$2892,$A14,'Lineage Data'!$E$2:$E$2892,D$4) -> 0 | E14: =COUNTIFS('Lineage Data'!$C$2:$C$2892,$A14,'Lineage Data'!$E$2:$E$2892,E$4) -> 0 | F14: =COUNTIFS('Lineage Data'!$C$2:$C$2892,$A14,'Lineage Data'!$E$2:$E$2892,F$4) -> 0 | G14: =SUM(B14:F14) -> 94 | H14: =IF(G14=0,0,(B14+C14)/G14) -> 1 | I14: =IF(G14=0,0,(D14+E14)/G14) -> 0
A15: InstdAmt | B15: =COUNTIFS('Lineage Data'!$C$2:$C$2892,$A15,'Lineage Data'!$E$2:$E$2892,B$4) -> 16 | C15: =COUNTIFS('Lineage Data'!$C$2:$C$2892,$A15,'Lineage Data'!$E$2:$E$2892,C$4) -> 0 | D15: =COUNTIFS('Lineage Data'!$C$2:$C$2892,$A15,'Lineage Data'!$E$2:$E$2892,D$4) -> 0 | E15: =COUNTIFS('Lineage Data'!$C$2:$C$2892,$A15,'Lineage Data'!$E$2:$E$2892,E$4) -> 0 | F15: =COUNTIFS('Lineage Data'!$C$2:$C$2892,$A15,'Lineage Data'!$E$2:$E$2892,F$4) -> 0 | G15: =SUM(B15:F15) -> 16 | H15: =IF(G15=0,0,(B15+C15)/G15) -> 1 | I15: =IF(G15=0,0,(D15+E15)/G15) -> 0
A16: InstgAgt | B16: =COUNTIFS('Lineage Data'!$C$2:$C$2892,$A16,'Lineage Data'!$E$2:$E$2892,B$4) -> 94 | C16: =COUNTIFS('Lineage Data'!$C$2:$C$2892,$A16,'Lineage Data'!$E$2:$E$2892,C$4) -> 0 | D16: =COUNTIFS('Lineage Data'!$C$2:$C$2892,$A16,'Lineage Data'!$E$2:$E$2892,D$4) -> 0 | E16: =COUNTIFS('Lineage Data'!$C$2:$C$2892,$A16,'Lineage Data'!$E$2:$E$2892,E$4) -> 0 | F16: =COUNTIFS('Lineage Data'!$C$2:$C$2892,$A16,'Lineage Data'!$E$2:$E$2892,F$4) -> 0 | G16: =SUM(B16:F16) -> 94 | H16: =IF(G16=0,0,(B16+C16)/G16) -> 1 | I16: =IF(G16=0,0,(D16+E16)/G16) -> 0
... A25: XchgRate | B25: =COUNTIFS('Lineage Data'!$C$2:$C$2892,$A25,'Lineage Data'!$E$2:$E$2892,B$4) -> 14 | C25: =COUNTIFS('Lineage Data'!$C$2:$C$2892,$A25,'Lineage Data'!$E$2:$E$2892,C$4) -> 0 | D25: =COUNTIFS('Lineage Data'!$C$2:$C$2892,$A25,'Lineage Data'!$E$2:$E$2892,D$4) -> 0 | E25: =COUNTIFS('Lineage Data'!$C$2:$C$2892,$A25,'Lineage Data'!$E$2:$E$2892,E$4) -> 0 | F25: =COUNTIFS('Lineage Data'!$C$2:$C$2892,$A25,'Lineage Data'!$E$2:$E$2892,F$4) -> 0 | G25: =SUM(B25:F25) -> 14 | H25: =IF(G25=0,0,(B25+C25)/G25) -> 1 | I25: =IF(G25=0,0,(D25+E25)/G25) -> 0
A26: TOTAL | B26: =SUM(B5:B25) -> 1284 | C26: =SUM(C5:C25) -> 218 | D26: =SUM(D5:D25) -> 607 | E26: =SUM(E5:E25) -> 517 | F26: =SUM(F5:F25) -> 265 | G26: =SUM(G5:G25) -> 2891 | H26: =IF(G26=0,0,(B26+C26)/G26) -> 0.51954341 | I26: =IF(G26=0,0,(D26+E26)/G26) -> 0.38879281

Sheet Lineage Data
A1: Msg ID | B1: ISO 20022 element path | C1: Group | D1: Source in MT103 | E1: Method
A2: MSG001 | B2: GrpHdr/MsgId | C2: GrpHdr | D2: :20: | E2: DIRECT
A3: MSG001 | B3: GrpHdr/CreDtTm | C3: GrpHdr | D3: conversion time | E3: INFERRED
A4: MSG001 | B4: GrpHdr/NbOfTxs | C4: GrpHdr | D4: structure | E4: INFERRED
A5: MSG001 | B5: GrpHdr/SttlmInf/SttlmMtd | C5: GrpHdr | D5: :53A:/:54A: presence | E5: INFERRED
A6: MSG001 | B6: CdtTrfTxInf/PmtId/InstrId | C6: PmtId | D6: :20: | E6: DIRECT
A7: MSG001 | B7: CdtTrfTxInf/PmtId/EndToEndId | C7: PmtId | D7: no /ROC/ in :70: | E7: INFERRED
A8: MSG001 | B8: CdtTrfTxInf/PmtId/TxId | C8: PmtId | D8: :20: | E8: DIRECT
A9: MSG001 | B9: CdtTrfTxInf/PmtId/UETR | C9: PmtId | D9: generated by translator | E9: INFERRED
A10: MSG001 | B10: CdtTrfTxInf/IntrBkSttlmAmt | C10: IntrBkSttlmAmt | D10: :32A: | E10: DIRECT
A11: MSG001 | B11: CdtTrfTxInf/IntrBkSttlmDt | C11: IntrBkSttlmDt | D11: :32A: | E11: DIRECT
A12: MSG001 | B12: CdtTrfTxInf/ChrgBr | C12: ChrgBr | D12: :71A: | E12: CODE
... A2892: MSG100 | B2892: CdtTrfTxInf/RmtInf/Ustrd | C2892: RmtInf | D2892: :70: | E2892: FREETEXT

Sheet Address Data
A1: Msg ID | B1: Party role | C1: Country | D1: Town+Country present (1/0) | E1: Street structured (1/0) | F1: Has AdrLine (1/0)
A2: MSG001 | B2: Dbtr | C2: CN | D2: 1 | E2: 1 | F2: 0
A3: MSG001 | B3: Cdtr | C3: PK | D3: 1 | E3: 0 | F3: 1
A4: MSG002 | B4: Dbtr | C4: GB | D4: 1 | E4: 0 | F4: 1
A5: MSG002 | B5: Cdtr | C5: PK | D5: 1 | E5: 0 | F5: 1
A6: MSG003 | B6: Dbtr | C6: GB | D6: 1 | E6: 1 | F6: 0
A7: MSG003 | B7: Cdtr | C7: PK | D7: 1 | E7: 1 | F7: 0
A8: MSG004 | B8: Dbtr | C8: US | D8: 1 | E8: 1 | F8: 0
A9: MSG004 | B9: Cdtr | C9: PK | D9: 1 | E9: 0 | F9: 1
A10: MSG005 | B10: Dbtr | C10: AE | D10: 1 | E10: 0 | F10: 1
A11: MSG005 | B11: Cdtr | C11: PK | D11: 1 | E11: 0 | F11: 1
A12: MSG006 | B12: Dbtr | C12: CN | D12: 1 | E12: 1 | F12: 0
A13: MSG006 | B13: Cdtr | C13: PK | D13: 1 | E13: 0 | F13: 1
... A189: MSG100 | B189: Cdtr | C189: PK | D189: 1 | E189: 1 | F189: 0
